<?xml version="1.0"?>
<robot name="my_robot">

<!-- Full course here with TF, URDF, Xacro, Gazebo, and more: https://rbcknd.com/ros2-tf-urdf-gazebo -->

    <material name="grey">
        <color rgba="0.7 0.7 0.7 1" />
    </material>

    <material name="green">
        <color rgba="0 0.6 0 1" />
    </material>
    
    <material name="white">
        <color rgba="1 1 1 1"/>
    </material>

    <link name="base_footprint"/>

    <link name="base_link">
        <visual>
            <geometry>
                <box size="0.6 0.4 0.2" />
            </geometry>
            <origin xyz="0 0 0.1" rpy="0 0 0" />
            <material name="green" />
        </visual>
    </link>
    
    <link name="lidar">
    	<visual>
    	    <geometry>
    	        <cylinder radius="0.1" length="0.05"/>
    	    </geometry>
    	    <origin xyz="0 0 0" rpy="0 0 0" />
    	    <material name="white" />
    	</visual>
    </link>

    <link name="left_wheel">
        <visual>
            <geometry>
                <cylinder radius="0.1" length="0.05"/>
            </geometry>
            <origin xyz="0 0 0" rpy="1.57 0 0" />
            <material name="grey" />
        </visual>
    </link>

    <link name="right_wheel">
        <visual>
            <geometry>
                <cylinder radius="0.1" length="0.05"/>
            </geometry>
            <origin xyz="0 0 0" rpy="1.57 0 0" />
            <material name="grey" />
        </visual>
    </link>

    <link name="caster_wheel">
        <visual>
            <geometry>
                <sphere radius="0.05"/>
            </geometry>
            <origin xyz="0 0 0" rpy="0 0 0" />
            <material name="grey" />
        </visual>
    </link>

    <joint name="base_joint" type="fixed">
        <parent link="base_footprint"/>
        <child link="base_link"/>
        <origin xyz="0 0 0.1" rpy="0 0 0"/>
    </joint>

    <joint name="base_lidar_joint" type="fixed">
        <parent link="base_link"/>
        <child link="lidar"/>
        <origin xyz="0 0 0.225" rpy="0 0 0"/>
    </joint>

    <joint name="base_left_wheel_joint" type="continuous">
        <parent link="base_link"/>
        <child link="left_wheel"/>
        <origin xyz="-0.15 0.225 0" rpy="0 0 0"/>
        <axis xyz="0 1 0"/>
    </joint>

    <joint name="base_right_wheel_joint" type="continuous">
        <parent link="base_link"/>
        <child link="right_wheel"/>
        <origin xyz="-0.15 -0.225 0" rpy="0 0 0"/>
        <axis xyz="0 1 0"/>
    </joint>

    <joint name="base_caster_wheel_joint" type="fixed">
        <parent link="base_link"/>
        <child link="caster_wheel"/>
        <origin xyz="0.2 0 -0.05" rpy="0 0 0"/>
    </joint>

    <!-- Gazebo Plugins -->
    <gazebo>
        <plugin name="differential_drive_controller" filename="libgazebo_ros_diff_drive.so">
            <ros>
                <namespace>/my_robot</namespace>
            </ros>
            <update_rate>50</update_rate>
            <left_joint>base_left_wheel_joint</left_joint>
            <right_joint>base_right_wheel_joint</right_joint>
            <wheel_separation>0.45</wheel_separation>
            <wheel_radius>0.1</wheel_radius>
            <odom_topic>odom</odom_topic>
            <robot_base_frame>base_link</robot_base_frame>
        </plugin>
    </gazebo>

    <gazebo>
        <plugin name="gazebo_ros_laser" filename="libgazebo_ros_laser.so">
            <topic_name>/scan</topic_name>
            <frame_name>lidar</frame_name>
        </plugin>
    </gazebo>

</robot>